DEBUG:botocore.hooks:Changing event name from creating-client-class.iot-data to creating-client-class.iot-data-plane
DEBUG:botocore.hooks:Changing event name from before-call.apigateway to before-call.api-gateway
DEBUG:botocore.hooks:Changing event name from request-created.machinelearning.Predict to request-created.machine-learning.Predict
DEBUG:botocore.hooks:Changing event name from before-parameter-build.autoscaling.CreateLaunchConfiguration to before-parameter-build.auto-scaling.CreateLaunchConfiguration
DEBUG:botocore.hooks:Changing event name from before-parameter-build.route53 to before-parameter-build.route-53
DEBUG:botocore.hooks:Changing event name from request-created.cloudsearchdomain.Search to request-created.cloudsearch-domain.Search
DEBUG:botocore.hooks:Changing event name from docs.*.autoscaling.CreateLaunchConfiguration.complete-section to docs.*.auto-scaling.CreateLaunchConfiguration.complete-section
DEBUG:botocore.hooks:Changing event name from before-parameter-build.logs.CreateExportTask to before-parameter-build.cloudwatch-logs.CreateExportTask
DEBUG:botocore.hooks:Changing event name from docs.*.logs.CreateExportTask.complete-section to docs.*.cloudwatch-logs.CreateExportTask.complete-section
DEBUG:botocore.hooks:Changing event name from before-parameter-build.cloudsearchdomain.Search to before-parameter-build.cloudsearch-domain.Search
DEBUG:botocore.hooks:Changing event name from docs.*.cloudsearchdomain.Search.complete-section to docs.*.cloudsearch-domain.Search.complete-section
DEBUG:botocore.utils:IMDS ENDPOINT: http://169.254.169.254/
DEBUG:botocore.credentials:Looking for credentials via: env
DEBUG:botocore.credentials:Looking for credentials via: assume-role
DEBUG:botocore.credentials:Looking for credentials via: assume-role-with-web-identity
DEBUG:botocore.credentials:Looking for credentials via: sso
DEBUG:botocore.credentials:Looking for credentials via: shared-credentials-file
DEBUG:botocore.credentials:Looking for credentials via: custom-process
DEBUG:botocore.credentials:Looking for credentials via: config-file
DEBUG:botocore.credentials:Looking for credentials via: ec2-credentials-file
DEBUG:botocore.credentials:Looking for credentials via: boto-config
DEBUG:botocore.credentials:Looking for credentials via: container-role
DEBUG:botocore.credentials:Looking for credentials via: iam-role
DEBUG:urllib3.connectionpool:Starting new HTTP connection (1): 169.254.169.254:80
DEBUG:botocore.utils:Caught retryable HTTP exception while making metadata service request to http://169.254.169.254/latest/api/token: Connect timeout on endpoint URL: "http://169.254.169.254/latest/api/token"
Traceback (most recent call last):
  File "C:\Users\hp\AppData\Local\Programs\Python\Python37\lib\site-packages\urllib3\connection.py", line 175, in _new_conn
    (self._dns_host, self.port), self.timeout, **extra_kw
  File "C:\Users\hp\AppData\Local\Programs\Python\Python37\lib\site-packages\urllib3\util\connection.py", line 95, in create_connection
    raise err
  File "C:\Users\hp\AppData\Local\Programs\Python\Python37\lib\site-packages\urllib3\util\connection.py", line 85, in create_connection
    sock.connect(sa)
socket.timeout: timed out

During handling of the above exception, another exception occurred:

Traceback (most recent call last):
  File "C:\Users\hp\AppData\Local\Programs\Python\Python37\lib\site-packages\botocore\httpsession.py", line 464, in send
    chunked=self._chunked(request.headers),
  File "C:\Users\hp\AppData\Local\Programs\Python\Python37\lib\site-packages\urllib3\connectionpool.py", line 788, in urlopen
    method, url, error=e, _pool=self, _stacktrace=sys.exc_info()[2]
  File "C:\Users\hp\AppData\Local\Programs\Python\Python37\lib\site-packages\urllib3\util\retry.py", line 525, in increment
    raise six.reraise(type(error), error, _stacktrace)
  File "C:\Users\hp\AppData\Local\Programs\Python\Python37\lib\site-packages\urllib3\packages\six.py", line 770, in reraise
    raise value
  File "C:\Users\hp\AppData\Local\Programs\Python\Python37\lib\site-packages\urllib3\connectionpool.py", line 710, in urlopen
    chunked=chunked,
  File "C:\Users\hp\AppData\Local\Programs\Python\Python37\lib\site-packages\urllib3\connectionpool.py", line 398, in _make_request
    conn.request(method, url, **httplib_request_kw)
  File "C:\Users\hp\AppData\Local\Programs\Python\Python37\lib\site-packages\urllib3\connection.py", line 239, in request
    super(HTTPConnection, self).request(method, url, body=body, headers=headers)
  File "C:\Users\hp\AppData\Local\Programs\Python\Python37\lib\http\client.py", line 1262, in request
    self._send_request(method, url, body, headers, encode_chunked)
  File "C:\Users\hp\AppData\Local\Programs\Python\Python37\lib\site-packages\botocore\awsrequest.py", line 95, in _send_request
    method, url, body, headers, *args, **kwargs
  File "C:\Users\hp\AppData\Local\Programs\Python\Python37\lib\http\client.py", line 1308, in _send_request
    self.endheaders(body, encode_chunked=encode_chunked)
  File "C:\Users\hp\AppData\Local\Programs\Python\Python37\lib\http\client.py", line 1257, in endheaders
    self._send_output(message_body, encode_chunked=encode_chunked)
  File "C:\Users\hp\AppData\Local\Programs\Python\Python37\lib\site-packages\botocore\awsrequest.py", line 123, in _send_output
    self.send(msg)
  File "C:\Users\hp\AppData\Local\Programs\Python\Python37\lib\site-packages\botocore\awsrequest.py", line 218, in send
    return super().send(str)
  File "C:\Users\hp\AppData\Local\Programs\Python\Python37\lib\http\client.py", line 968, in send
    self.connect()
  File "C:\Users\hp\AppData\Local\Programs\Python\Python37\lib\site-packages\urllib3\connection.py", line 205, in connect
    conn = self._new_conn()
  File "C:\Users\hp\AppData\Local\Programs\Python\Python37\lib\site-packages\urllib3\connection.py", line 182, in _new_conn
    % (self.host, self.timeout),
urllib3.exceptions.ConnectTimeoutError: (<botocore.awsrequest.AWSHTTPConnection object at 0x000001C69AF418C8>, 'Connection to 169.254.169.254 timed out. (connect timeout=1)')

During handling of the above exception, another exception occurred:

Traceback (most recent call last):
  File "C:\Users\hp\AppData\Local\Programs\Python\Python37\lib\site-packages\botocore\utils.py", line 457, in _fetch_metadata_token
    response = self._session.send(request.prepare())
  File "C:\Users\hp\AppData\Local\Programs\Python\Python37\lib\site-packages\botocore\httpsession.py", line 490, in send
    raise ConnectTimeoutError(endpoint_url=request.url, error=e)
botocore.exceptions.ConnectTimeoutError: Connect timeout on endpoint URL: "http://169.254.169.254/latest/api/token"
DEBUG:urllib3.connectionpool:Starting new HTTP connection (2): 169.254.169.254:80
DEBUG:botocore.utils:Caught retryable HTTP exception while making metadata service request to http://169.254.169.254/latest/meta-data/iam/security-credentials/: Connect timeout on endpoint URL: "http://169.254.169.254/latest/meta-data/iam/security-credentials/"
Traceback (most recent call last):
  File "C:\Users\hp\AppData\Local\Programs\Python\Python37\lib\site-packages\urllib3\connection.py", line 175, in _new_conn
    (self._dns_host, self.port), self.timeout, **extra_kw
  File "C:\Users\hp\AppData\Local\Programs\Python\Python37\lib\site-packages\urllib3\util\connection.py", line 95, in create_connection
    raise err
  File "C:\Users\hp\AppData\Local\Programs\Python\Python37\lib\site-packages\urllib3\util\connection.py", line 85, in create_connection
    sock.connect(sa)
socket.timeout: timed out

During handling of the above exception, another exception occurred:

Traceback (most recent call last):
  File "C:\Users\hp\AppData\Local\Programs\Python\Python37\lib\site-packages\botocore\httpsession.py", line 464, in send
    chunked=self._chunked(request.headers),
  File "C:\Users\hp\AppData\Local\Programs\Python\Python37\lib\site-packages\urllib3\connectionpool.py", line 788, in urlopen
    method, url, error=e, _pool=self, _stacktrace=sys.exc_info()[2]
  File "C:\Users\hp\AppData\Local\Programs\Python\Python37\lib\site-packages\urllib3\util\retry.py", line 525, in increment
    raise six.reraise(type(error), error, _stacktrace)
  File "C:\Users\hp\AppData\Local\Programs\Python\Python37\lib\site-packages\urllib3\packages\six.py", line 770, in reraise
    raise value
  File "C:\Users\hp\AppData\Local\Programs\Python\Python37\lib\site-packages\urllib3\connectionpool.py", line 710, in urlopen
    chunked=chunked,
  File "C:\Users\hp\AppData\Local\Programs\Python\Python37\lib\site-packages\urllib3\connectionpool.py", line 398, in _make_request
    conn.request(method, url, **httplib_request_kw)
  File "C:\Users\hp\AppData\Local\Programs\Python\Python37\lib\site-packages\urllib3\connection.py", line 239, in request
    super(HTTPConnection, self).request(method, url, body=body, headers=headers)
  File "C:\Users\hp\AppData\Local\Programs\Python\Python37\lib\http\client.py", line 1262, in request
    self._send_request(method, url, body, headers, encode_chunked)
  File "C:\Users\hp\AppData\Local\Programs\Python\Python37\lib\site-packages\botocore\awsrequest.py", line 95, in _send_request
    method, url, body, headers, *args, **kwargs
  File "C:\Users\hp\AppData\Local\Programs\Python\Python37\lib\http\client.py", line 1308, in _send_request
    self.endheaders(body, encode_chunked=encode_chunked)
  File "C:\Users\hp\AppData\Local\Programs\Python\Python37\lib\http\client.py", line 1257, in endheaders
    self._send_output(message_body, encode_chunked=encode_chunked)
  File "C:\Users\hp\AppData\Local\Programs\Python\Python37\lib\site-packages\botocore\awsrequest.py", line 123, in _send_output
    self.send(msg)
  File "C:\Users\hp\AppData\Local\Programs\Python\Python37\lib\site-packages\botocore\awsrequest.py", line 218, in send
    return super().send(str)
  File "C:\Users\hp\AppData\Local\Programs\Python\Python37\lib\http\client.py", line 968, in send
    self.connect()
  File "C:\Users\hp\AppData\Local\Programs\Python\Python37\lib\site-packages\urllib3\connection.py", line 205, in connect
    conn = self._new_conn()
  File "C:\Users\hp\AppData\Local\Programs\Python\Python37\lib\site-packages\urllib3\connection.py", line 182, in _new_conn
    % (self.host, self.timeout),
urllib3.exceptions.ConnectTimeoutError: (<botocore.awsrequest.AWSHTTPConnection object at 0x000001C69B017A88>, 'Connection to 169.254.169.254 timed out. (connect timeout=1)')

During handling of the above exception, another exception occurred:

Traceback (most recent call last):
  File "C:\Users\hp\AppData\Local\Programs\Python\Python37\lib\site-packages\botocore\utils.py", line 510, in _get_request
    response = self._session.send(request.prepare())
  File "C:\Users\hp\AppData\Local\Programs\Python\Python37\lib\site-packages\botocore\httpsession.py", line 490, in send
    raise ConnectTimeoutError(endpoint_url=request.url, error=e)
botocore.exceptions.ConnectTimeoutError: Connect timeout on endpoint URL: "http://169.254.169.254/latest/meta-data/iam/security-credentials/"
DEBUG:botocore.utils:Max number of attempts exceeded (1) when attempting to retrieve data from metadata service.
DEBUG:botocore.loaders:Loading JSON file: C:\Users\hp\AppData\Local\Programs\Python\Python37\lib\site-packages\botocore\data\endpoints.json
DEBUG:botocore.loaders:Loading JSON file: C:\Users\hp\AppData\Local\Programs\Python\Python37\lib\site-packages\botocore\data\sdk-default-configuration.json
DEBUG:botocore.hooks:Event choose-service-name: calling handler <function handle_service_name_alias at 0x000001C69AE09EE8>
DEBUG:botocore.loaders:Loading JSON file: C:\Users\hp\AppData\Local\Programs\Python\Python37\lib\site-packages\botocore\data\s3\2006-03-01\service-2.json
DEBUG:botocore.loaders:Loading JSON file: C:\Users\hp\AppData\Local\Programs\Python\Python37\lib\site-packages\botocore\data\s3\2006-03-01\endpoint-rule-set-1.json.gz
DEBUG:botocore.loaders:Loading JSON file: C:\Users\hp\AppData\Local\Programs\Python\Python37\lib\site-packages\botocore\data\partitions.json
DEBUG:botocore.hooks:Event creating-client-class.s3: calling handler <function add_generate_presigned_post at 0x000001C69ADAFDC8>
DEBUG:botocore.hooks:Event creating-client-class.s3: calling handler <function lazy_call.<locals>._handler at 0x000001C69843F678>
DEBUG:botocore.hooks:Event creating-client-class.s3: calling handler <function add_generate_presigned_url at 0x000001C69ADAFB88>
DEBUG:botocore.endpoint:Setting s3 timeout as (60, 60)
DEBUG:botocore.loaders:Loading JSON file: C:\Users\hp\AppData\Local\Programs\Python\Python37\lib\site-packages\botocore\data\_retry.json
DEBUG:botocore.client:Registering retry handlers for service: s3
DEBUG:botocore.utils:Registering S3 region redirector handler
DEBUG:botocore.hooks:Changing event name from creating-client-class.iot-data to creating-client-class.iot-data-plane
DEBUG:botocore.hooks:Changing event name from before-call.apigateway to before-call.api-gateway
DEBUG:botocore.hooks:Changing event name from request-created.machinelearning.Predict to request-created.machine-learning.Predict
DEBUG:botocore.hooks:Changing event name from before-parameter-build.autoscaling.CreateLaunchConfiguration to before-parameter-build.auto-scaling.CreateLaunchConfiguration
DEBUG:botocore.hooks:Changing event name from before-parameter-build.route53 to before-parameter-build.route-53
DEBUG:botocore.hooks:Changing event name from request-created.cloudsearchdomain.Search to request-created.cloudsearch-domain.Search
DEBUG:botocore.hooks:Changing event name from docs.*.autoscaling.CreateLaunchConfiguration.complete-section to docs.*.auto-scaling.CreateLaunchConfiguration.complete-section
DEBUG:botocore.hooks:Changing event name from before-parameter-build.logs.CreateExportTask to before-parameter-build.cloudwatch-logs.CreateExportTask
DEBUG:botocore.hooks:Changing event name from docs.*.logs.CreateExportTask.complete-section to docs.*.cloudwatch-logs.CreateExportTask.complete-section
DEBUG:botocore.hooks:Changing event name from before-parameter-build.cloudsearchdomain.Search to before-parameter-build.cloudsearch-domain.Search
DEBUG:botocore.hooks:Changing event name from docs.*.cloudsearchdomain.Search.complete-section to docs.*.cloudsearch-domain.Search.complete-section
DEBUG:botocore.utils:IMDS ENDPOINT: http://169.254.169.254/
DEBUG:botocore.credentials:Looking for credentials via: env
DEBUG:botocore.credentials:Looking for credentials via: assume-role
DEBUG:botocore.credentials:Looking for credentials via: assume-role-with-web-identity
DEBUG:botocore.credentials:Looking for credentials via: sso
DEBUG:botocore.credentials:Looking for credentials via: shared-credentials-file
DEBUG:botocore.credentials:Looking for credentials via: custom-process
DEBUG:botocore.credentials:Looking for credentials via: config-file
DEBUG:botocore.credentials:Looking for credentials via: ec2-credentials-file
DEBUG:botocore.credentials:Looking for credentials via: boto-config
DEBUG:botocore.credentials:Looking for credentials via: container-role
DEBUG:botocore.credentials:Looking for credentials via: iam-role
DEBUG:urllib3.connectionpool:Starting new HTTP connection (1): 169.254.169.254:80
DEBUG:botocore.utils:Caught retryable HTTP exception while making metadata service request to http://169.254.169.254/latest/api/token: Connect timeout on endpoint URL: "http://169.254.169.254/latest/api/token"
Traceback (most recent call last):
  File "c:\Users\hp\AppData\Local\Programs\Python\Python37\lib\site-packages\urllib3\connection.py", line 175, in _new_conn
    (self._dns_host, self.port), self.timeout, **extra_kw
  File "c:\Users\hp\AppData\Local\Programs\Python\Python37\lib\site-packages\urllib3\util\connection.py", line 95, in create_connection
    raise err
  File "c:\Users\hp\AppData\Local\Programs\Python\Python37\lib\site-packages\urllib3\util\connection.py", line 85, in create_connection
    sock.connect(sa)
socket.timeout: timed out

During handling of the above exception, another exception occurred:

Traceback (most recent call last):
  File "c:\Users\hp\AppData\Local\Programs\Python\Python37\lib\site-packages\botocore\httpsession.py", line 464, in send
    chunked=self._chunked(request.headers),
  File "c:\Users\hp\AppData\Local\Programs\Python\Python37\lib\site-packages\urllib3\connectionpool.py", line 788, in urlopen
    method, url, error=e, _pool=self, _stacktrace=sys.exc_info()[2]
  File "c:\Users\hp\AppData\Local\Programs\Python\Python37\lib\site-packages\urllib3\util\retry.py", line 525, in increment
    raise six.reraise(type(error), error, _stacktrace)
  File "c:\Users\hp\AppData\Local\Programs\Python\Python37\lib\site-packages\urllib3\packages\six.py", line 770, in reraise
    raise value
  File "c:\Users\hp\AppData\Local\Programs\Python\Python37\lib\site-packages\urllib3\connectionpool.py", line 710, in urlopen
    chunked=chunked,
  File "c:\Users\hp\AppData\Local\Programs\Python\Python37\lib\site-packages\urllib3\connectionpool.py", line 398, in _make_request
    conn.request(method, url, **httplib_request_kw)
  File "c:\Users\hp\AppData\Local\Programs\Python\Python37\lib\site-packages\urllib3\connection.py", line 239, in request
    super(HTTPConnection, self).request(method, url, body=body, headers=headers)
  File "c:\Users\hp\AppData\Local\Programs\Python\Python37\lib\http\client.py", line 1262, in request
    self._send_request(method, url, body, headers, encode_chunked)
  File "c:\Users\hp\AppData\Local\Programs\Python\Python37\lib\site-packages\botocore\awsrequest.py", line 95, in _send_request
    method, url, body, headers, *args, **kwargs
  File "c:\Users\hp\AppData\Local\Programs\Python\Python37\lib\http\client.py", line 1308, in _send_request
    self.endheaders(body, encode_chunked=encode_chunked)
  File "c:\Users\hp\AppData\Local\Programs\Python\Python37\lib\http\client.py", line 1257, in endheaders
    self._send_output(message_body, encode_chunked=encode_chunked)
  File "c:\Users\hp\AppData\Local\Programs\Python\Python37\lib\site-packages\botocore\awsrequest.py", line 123, in _send_output
    self.send(msg)
  File "c:\Users\hp\AppData\Local\Programs\Python\Python37\lib\site-packages\botocore\awsrequest.py", line 218, in send
    return super().send(str)
  File "c:\Users\hp\AppData\Local\Programs\Python\Python37\lib\http\client.py", line 968, in send
    self.connect()
  File "c:\Users\hp\AppData\Local\Programs\Python\Python37\lib\site-packages\urllib3\connection.py", line 205, in connect
    conn = self._new_conn()
  File "c:\Users\hp\AppData\Local\Programs\Python\Python37\lib\site-packages\urllib3\connection.py", line 182, in _new_conn
    % (self.host, self.timeout),
urllib3.exceptions.ConnectTimeoutError: (<botocore.awsrequest.AWSHTTPConnection object at 0x00000203E3CD7948>, 'Connection to 169.254.169.254 timed out. (connect timeout=1)')

During handling of the above exception, another exception occurred:

Traceback (most recent call last):
  File "c:\Users\hp\AppData\Local\Programs\Python\Python37\lib\site-packages\botocore\utils.py", line 457, in _fetch_metadata_token
    response = self._session.send(request.prepare())
  File "c:\Users\hp\AppData\Local\Programs\Python\Python37\lib\site-packages\botocore\httpsession.py", line 490, in send
    raise ConnectTimeoutError(endpoint_url=request.url, error=e)
botocore.exceptions.ConnectTimeoutError: Connect timeout on endpoint URL: "http://169.254.169.254/latest/api/token"
DEBUG:urllib3.connectionpool:Starting new HTTP connection (2): 169.254.169.254:80
DEBUG:botocore.utils:Caught retryable HTTP exception while making metadata service request to http://169.254.169.254/latest/meta-data/iam/security-credentials/: Connect timeout on endpoint URL: "http://169.254.169.254/latest/meta-data/iam/security-credentials/"
Traceback (most recent call last):
  File "c:\Users\hp\AppData\Local\Programs\Python\Python37\lib\site-packages\urllib3\connection.py", line 175, in _new_conn
    (self._dns_host, self.port), self.timeout, **extra_kw
  File "c:\Users\hp\AppData\Local\Programs\Python\Python37\lib\site-packages\urllib3\util\connection.py", line 95, in create_connection
    raise err
  File "c:\Users\hp\AppData\Local\Programs\Python\Python37\lib\site-packages\urllib3\util\connection.py", line 85, in create_connection
    sock.connect(sa)
socket.timeout: timed out

During handling of the above exception, another exception occurred:

Traceback (most recent call last):
  File "c:\Users\hp\AppData\Local\Programs\Python\Python37\lib\site-packages\botocore\httpsession.py", line 464, in send
    chunked=self._chunked(request.headers),
  File "c:\Users\hp\AppData\Local\Programs\Python\Python37\lib\site-packages\urllib3\connectionpool.py", line 788, in urlopen
    method, url, error=e, _pool=self, _stacktrace=sys.exc_info()[2]
  File "c:\Users\hp\AppData\Local\Programs\Python\Python37\lib\site-packages\urllib3\util\retry.py", line 525, in increment
    raise six.reraise(type(error), error, _stacktrace)
  File "c:\Users\hp\AppData\Local\Programs\Python\Python37\lib\site-packages\urllib3\packages\six.py", line 770, in reraise
    raise value
  File "c:\Users\hp\AppData\Local\Programs\Python\Python37\lib\site-packages\urllib3\connectionpool.py", line 710, in urlopen
    chunked=chunked,
  File "c:\Users\hp\AppData\Local\Programs\Python\Python37\lib\site-packages\urllib3\connectionpool.py", line 398, in _make_request
    conn.request(method, url, **httplib_request_kw)
  File "c:\Users\hp\AppData\Local\Programs\Python\Python37\lib\site-packages\urllib3\connection.py", line 239, in request
    super(HTTPConnection, self).request(method, url, body=body, headers=headers)
  File "c:\Users\hp\AppData\Local\Programs\Python\Python37\lib\http\client.py", line 1262, in request
    self._send_request(method, url, body, headers, encode_chunked)
  File "c:\Users\hp\AppData\Local\Programs\Python\Python37\lib\site-packages\botocore\awsrequest.py", line 95, in _send_request
    method, url, body, headers, *args, **kwargs
  File "c:\Users\hp\AppData\Local\Programs\Python\Python37\lib\http\client.py", line 1308, in _send_request
    self.endheaders(body, encode_chunked=encode_chunked)
  File "c:\Users\hp\AppData\Local\Programs\Python\Python37\lib\http\client.py", line 1257, in endheaders
    self._send_output(message_body, encode_chunked=encode_chunked)
  File "c:\Users\hp\AppData\Local\Programs\Python\Python37\lib\site-packages\botocore\awsrequest.py", line 123, in _send_output
    self.send(msg)
  File "c:\Users\hp\AppData\Local\Programs\Python\Python37\lib\site-packages\botocore\awsrequest.py", line 218, in send
    return super().send(str)
  File "c:\Users\hp\AppData\Local\Programs\Python\Python37\lib\http\client.py", line 968, in send
    self.connect()
  File "c:\Users\hp\AppData\Local\Programs\Python\Python37\lib\site-packages\urllib3\connection.py", line 205, in connect
    conn = self._new_conn()
  File "c:\Users\hp\AppData\Local\Programs\Python\Python37\lib\site-packages\urllib3\connection.py", line 182, in _new_conn
    % (self.host, self.timeout),
urllib3.exceptions.ConnectTimeoutError: (<botocore.awsrequest.AWSHTTPConnection object at 0x00000203E69EAA08>, 'Connection to 169.254.169.254 timed out. (connect timeout=1)')

During handling of the above exception, another exception occurred:

Traceback (most recent call last):
  File "c:\Users\hp\AppData\Local\Programs\Python\Python37\lib\site-packages\botocore\utils.py", line 510, in _get_request
    response = self._session.send(request.prepare())
  File "c:\Users\hp\AppData\Local\Programs\Python\Python37\lib\site-packages\botocore\httpsession.py", line 490, in send
    raise ConnectTimeoutError(endpoint_url=request.url, error=e)
botocore.exceptions.ConnectTimeoutError: Connect timeout on endpoint URL: "http://169.254.169.254/latest/meta-data/iam/security-credentials/"
DEBUG:botocore.utils:Max number of attempts exceeded (1) when attempting to retrieve data from metadata service.
DEBUG:botocore.loaders:Loading JSON file: c:\Users\hp\AppData\Local\Programs\Python\Python37\lib\site-packages\botocore\data\endpoints.json
DEBUG:botocore.loaders:Loading JSON file: c:\Users\hp\AppData\Local\Programs\Python\Python37\lib\site-packages\botocore\data\sdk-default-configuration.json
DEBUG:botocore.hooks:Event choose-service-name: calling handler <function handle_service_name_alias at 0x00000203E66BB048>
DEBUG:botocore.loaders:Loading JSON file: c:\Users\hp\AppData\Local\Programs\Python\Python37\lib\site-packages\botocore\data\s3\2006-03-01\service-2.json
DEBUG:botocore.loaders:Loading JSON file: c:\Users\hp\AppData\Local\Programs\Python\Python37\lib\site-packages\botocore\data\s3\2006-03-01\endpoint-rule-set-1.json.gz
DEBUG:botocore.loaders:Loading JSON file: c:\Users\hp\AppData\Local\Programs\Python\Python37\lib\site-packages\botocore\data\partitions.json
DEBUG:botocore.hooks:Event creating-client-class.s3: calling handler <function add_generate_presigned_post at 0x00000203E6664AF8>
DEBUG:botocore.hooks:Event creating-client-class.s3: calling handler <function lazy_call.<locals>._handler at 0x00000203E5678F78>
DEBUG:botocore.hooks:Event creating-client-class.s3: calling handler <function add_generate_presigned_url at 0x00000203E66648B8>
DEBUG:botocore.endpoint:Setting s3 timeout as (60, 60)
DEBUG:botocore.loaders:Loading JSON file: c:\Users\hp\AppData\Local\Programs\Python\Python37\lib\site-packages\botocore\data\_retry.json
DEBUG:botocore.client:Registering retry handlers for service: s3
DEBUG:botocore.utils:Registering S3 region redirector handler
DEBUG:botocore.credentials:Looking for credentials via: env
DEBUG:botocore.credentials:Looking for credentials via: assume-role
DEBUG:botocore.credentials:Looking for credentials via: assume-role-with-web-identity
DEBUG:botocore.credentials:Looking for credentials via: sso
DEBUG:botocore.credentials:Looking for credentials via: shared-credentials-file
DEBUG:botocore.credentials:Looking for credentials via: custom-process
DEBUG:botocore.credentials:Looking for credentials via: config-file
DEBUG:botocore.credentials:Looking for credentials via: ec2-credentials-file
DEBUG:botocore.credentials:Looking for credentials via: boto-config
DEBUG:botocore.credentials:Looking for credentials via: container-role
DEBUG:botocore.credentials:Looking for credentials via: iam-role
DEBUG:urllib3.connectionpool:Starting new HTTP connection (3): 169.254.169.254:80
DEBUG:botocore.utils:Caught retryable HTTP exception while making metadata service request to http://169.254.169.254/latest/api/token: Connect timeout on endpoint URL: "http://169.254.169.254/latest/api/token"
Traceback (most recent call last):
  File "c:\Users\hp\AppData\Local\Programs\Python\Python37\lib\site-packages\urllib3\connection.py", line 175, in _new_conn
    (self._dns_host, self.port), self.timeout, **extra_kw
  File "c:\Users\hp\AppData\Local\Programs\Python\Python37\lib\site-packages\urllib3\util\connection.py", line 95, in create_connection
    raise err
  File "c:\Users\hp\AppData\Local\Programs\Python\Python37\lib\site-packages\urllib3\util\connection.py", line 85, in create_connection
    sock.connect(sa)
socket.timeout: timed out

During handling of the above exception, another exception occurred:

Traceback (most recent call last):
  File "c:\Users\hp\AppData\Local\Programs\Python\Python37\lib\site-packages\botocore\httpsession.py", line 464, in send
    chunked=self._chunked(request.headers),
  File "c:\Users\hp\AppData\Local\Programs\Python\Python37\lib\site-packages\urllib3\connectionpool.py", line 788, in urlopen
    method, url, error=e, _pool=self, _stacktrace=sys.exc_info()[2]
  File "c:\Users\hp\AppData\Local\Programs\Python\Python37\lib\site-packages\urllib3\util\retry.py", line 525, in increment
    raise six.reraise(type(error), error, _stacktrace)
  File "c:\Users\hp\AppData\Local\Programs\Python\Python37\lib\site-packages\urllib3\packages\six.py", line 770, in reraise
    raise value
  File "c:\Users\hp\AppData\Local\Programs\Python\Python37\lib\site-packages\urllib3\connectionpool.py", line 710, in urlopen
    chunked=chunked,
  File "c:\Users\hp\AppData\Local\Programs\Python\Python37\lib\site-packages\urllib3\connectionpool.py", line 398, in _make_request
    conn.request(method, url, **httplib_request_kw)
  File "c:\Users\hp\AppData\Local\Programs\Python\Python37\lib\site-packages\urllib3\connection.py", line 239, in request
    super(HTTPConnection, self).request(method, url, body=body, headers=headers)
  File "c:\Users\hp\AppData\Local\Programs\Python\Python37\lib\http\client.py", line 1262, in request
    self._send_request(method, url, body, headers, encode_chunked)
  File "c:\Users\hp\AppData\Local\Programs\Python\Python37\lib\site-packages\botocore\awsrequest.py", line 95, in _send_request
    method, url, body, headers, *args, **kwargs
  File "c:\Users\hp\AppData\Local\Programs\Python\Python37\lib\http\client.py", line 1308, in _send_request
    self.endheaders(body, encode_chunked=encode_chunked)
  File "c:\Users\hp\AppData\Local\Programs\Python\Python37\lib\http\client.py", line 1257, in endheaders
    self._send_output(message_body, encode_chunked=encode_chunked)
  File "c:\Users\hp\AppData\Local\Programs\Python\Python37\lib\site-packages\botocore\awsrequest.py", line 123, in _send_output
    self.send(msg)
  File "c:\Users\hp\AppData\Local\Programs\Python\Python37\lib\site-packages\botocore\awsrequest.py", line 218, in send
    return super().send(str)
  File "c:\Users\hp\AppData\Local\Programs\Python\Python37\lib\http\client.py", line 968, in send
    self.connect()
  File "c:\Users\hp\AppData\Local\Programs\Python\Python37\lib\site-packages\urllib3\connection.py", line 205, in connect
    conn = self._new_conn()
  File "c:\Users\hp\AppData\Local\Programs\Python\Python37\lib\site-packages\urllib3\connection.py", line 182, in _new_conn
    % (self.host, self.timeout),
urllib3.exceptions.ConnectTimeoutError: (<botocore.awsrequest.AWSHTTPConnection object at 0x00000203E60FD308>, 'Connection to 169.254.169.254 timed out. (connect timeout=1)')

During handling of the above exception, another exception occurred:

Traceback (most recent call last):
  File "c:\Users\hp\AppData\Local\Programs\Python\Python37\lib\site-packages\botocore\utils.py", line 457, in _fetch_metadata_token
    response = self._session.send(request.prepare())
  File "c:\Users\hp\AppData\Local\Programs\Python\Python37\lib\site-packages\botocore\httpsession.py", line 490, in send
    raise ConnectTimeoutError(endpoint_url=request.url, error=e)
botocore.exceptions.ConnectTimeoutError: Connect timeout on endpoint URL: "http://169.254.169.254/latest/api/token"
DEBUG:urllib3.connectionpool:Starting new HTTP connection (4): 169.254.169.254:80
DEBUG:botocore.utils:Caught retryable HTTP exception while making metadata service request to http://169.254.169.254/latest/meta-data/iam/security-credentials/: Connect timeout on endpoint URL: "http://169.254.169.254/latest/meta-data/iam/security-credentials/"
Traceback (most recent call last):
  File "c:\Users\hp\AppData\Local\Programs\Python\Python37\lib\site-packages\urllib3\connection.py", line 175, in _new_conn
    (self._dns_host, self.port), self.timeout, **extra_kw
  File "c:\Users\hp\AppData\Local\Programs\Python\Python37\lib\site-packages\urllib3\util\connection.py", line 95, in create_connection
    raise err
  File "c:\Users\hp\AppData\Local\Programs\Python\Python37\lib\site-packages\urllib3\util\connection.py", line 85, in create_connection
    sock.connect(sa)
socket.timeout: timed out

During handling of the above exception, another exception occurred:

Traceback (most recent call last):
  File "c:\Users\hp\AppData\Local\Programs\Python\Python37\lib\site-packages\botocore\httpsession.py", line 464, in send
    chunked=self._chunked(request.headers),
  File "c:\Users\hp\AppData\Local\Programs\Python\Python37\lib\site-packages\urllib3\connectionpool.py", line 788, in urlopen
    method, url, error=e, _pool=self, _stacktrace=sys.exc_info()[2]
  File "c:\Users\hp\AppData\Local\Programs\Python\Python37\lib\site-packages\urllib3\util\retry.py", line 525, in increment
    raise six.reraise(type(error), error, _stacktrace)
  File "c:\Users\hp\AppData\Local\Programs\Python\Python37\lib\site-packages\urllib3\packages\six.py", line 770, in reraise
    raise value
  File "c:\Users\hp\AppData\Local\Programs\Python\Python37\lib\site-packages\urllib3\connectionpool.py", line 710, in urlopen
    chunked=chunked,
  File "c:\Users\hp\AppData\Local\Programs\Python\Python37\lib\site-packages\urllib3\connectionpool.py", line 398, in _make_request
    conn.request(method, url, **httplib_request_kw)
  File "c:\Users\hp\AppData\Local\Programs\Python\Python37\lib\site-packages\urllib3\connection.py", line 239, in request
    super(HTTPConnection, self).request(method, url, body=body, headers=headers)
  File "c:\Users\hp\AppData\Local\Programs\Python\Python37\lib\http\client.py", line 1262, in request
    self._send_request(method, url, body, headers, encode_chunked)
  File "c:\Users\hp\AppData\Local\Programs\Python\Python37\lib\site-packages\botocore\awsrequest.py", line 95, in _send_request
    method, url, body, headers, *args, **kwargs
  File "c:\Users\hp\AppData\Local\Programs\Python\Python37\lib\http\client.py", line 1308, in _send_request
    self.endheaders(body, encode_chunked=encode_chunked)
  File "c:\Users\hp\AppData\Local\Programs\Python\Python37\lib\http\client.py", line 1257, in endheaders
    self._send_output(message_body, encode_chunked=encode_chunked)
  File "c:\Users\hp\AppData\Local\Programs\Python\Python37\lib\site-packages\botocore\awsrequest.py", line 123, in _send_output
    self.send(msg)
  File "c:\Users\hp\AppData\Local\Programs\Python\Python37\lib\site-packages\botocore\awsrequest.py", line 218, in send
    return super().send(str)
  File "c:\Users\hp\AppData\Local\Programs\Python\Python37\lib\http\client.py", line 968, in send
    self.connect()
  File "c:\Users\hp\AppData\Local\Programs\Python\Python37\lib\site-packages\urllib3\connection.py", line 205, in connect
    conn = self._new_conn()
  File "c:\Users\hp\AppData\Local\Programs\Python\Python37\lib\site-packages\urllib3\connection.py", line 182, in _new_conn
    % (self.host, self.timeout),
urllib3.exceptions.ConnectTimeoutError: (<botocore.awsrequest.AWSHTTPConnection object at 0x00000203E610A648>, 'Connection to 169.254.169.254 timed out. (connect timeout=1)')

During handling of the above exception, another exception occurred:

Traceback (most recent call last):
  File "c:\Users\hp\AppData\Local\Programs\Python\Python37\lib\site-packages\botocore\utils.py", line 510, in _get_request
    response = self._session.send(request.prepare())
  File "c:\Users\hp\AppData\Local\Programs\Python\Python37\lib\site-packages\botocore\httpsession.py", line 490, in send
    raise ConnectTimeoutError(endpoint_url=request.url, error=e)
botocore.exceptions.ConnectTimeoutError: Connect timeout on endpoint URL: "http://169.254.169.254/latest/meta-data/iam/security-credentials/"
DEBUG:botocore.utils:Max number of attempts exceeded (1) when attempting to retrieve data from metadata service.
DEBUG:botocore.hooks:Event choose-service-name: calling handler <function handle_service_name_alias at 0x00000203E66BB048>
DEBUG:botocore.hooks:Event creating-client-class.s3: calling handler <function add_generate_presigned_post at 0x00000203E6664AF8>
DEBUG:botocore.hooks:Event creating-client-class.s3: calling handler <function lazy_call.<locals>._handler at 0x00000203E5678F78>
DEBUG:botocore.hooks:Event creating-client-class.s3: calling handler <function add_generate_presigned_url at 0x00000203E66648B8>
DEBUG:botocore.endpoint:Setting s3 timeout as (60, 60)
DEBUG:botocore.client:Registering retry handlers for service: s3
DEBUG:botocore.utils:Registering S3 region redirector handler
DEBUG:botocore.hooks:Changing event name from creating-client-class.iot-data to creating-client-class.iot-data-plane
DEBUG:botocore.hooks:Changing event name from before-call.apigateway to before-call.api-gateway
DEBUG:botocore.hooks:Changing event name from request-created.machinelearning.Predict to request-created.machine-learning.Predict
DEBUG:botocore.hooks:Changing event name from before-parameter-build.autoscaling.CreateLaunchConfiguration to before-parameter-build.auto-scaling.CreateLaunchConfiguration
DEBUG:botocore.hooks:Changing event name from before-parameter-build.route53 to before-parameter-build.route-53
DEBUG:botocore.hooks:Changing event name from request-created.cloudsearchdomain.Search to request-created.cloudsearch-domain.Search
DEBUG:botocore.hooks:Changing event name from docs.*.autoscaling.CreateLaunchConfiguration.complete-section to docs.*.auto-scaling.CreateLaunchConfiguration.complete-section
DEBUG:botocore.hooks:Changing event name from before-parameter-build.logs.CreateExportTask to before-parameter-build.cloudwatch-logs.CreateExportTask
DEBUG:botocore.hooks:Changing event name from docs.*.logs.CreateExportTask.complete-section to docs.*.cloudwatch-logs.CreateExportTask.complete-section
DEBUG:botocore.hooks:Changing event name from before-parameter-build.cloudsearchdomain.Search to before-parameter-build.cloudsearch-domain.Search
DEBUG:botocore.hooks:Changing event name from docs.*.cloudsearchdomain.Search.complete-section to docs.*.cloudsearch-domain.Search.complete-section
DEBUG:botocore.utils:IMDS ENDPOINT: http://169.254.169.254/
DEBUG:botocore.credentials:Looking for credentials via: env
DEBUG:botocore.credentials:Looking for credentials via: assume-role
DEBUG:botocore.credentials:Looking for credentials via: assume-role-with-web-identity
DEBUG:botocore.credentials:Looking for credentials via: sso
DEBUG:botocore.credentials:Looking for credentials via: shared-credentials-file
DEBUG:botocore.credentials:Looking for credentials via: custom-process
DEBUG:botocore.credentials:Looking for credentials via: config-file
DEBUG:botocore.credentials:Looking for credentials via: ec2-credentials-file
DEBUG:botocore.credentials:Looking for credentials via: boto-config
DEBUG:botocore.credentials:Looking for credentials via: container-role
DEBUG:botocore.credentials:Looking for credentials via: iam-role
DEBUG:urllib3.connectionpool:Starting new HTTP connection (1): 169.254.169.254:80
DEBUG:botocore.utils:Caught retryable HTTP exception while making metadata service request to http://169.254.169.254/latest/api/token: Connect timeout on endpoint URL: "http://169.254.169.254/latest/api/token"
Traceback (most recent call last):
  File "c:\Users\hp\AppData\Local\Programs\Python\Python37\lib\site-packages\urllib3\connection.py", line 175, in _new_conn
    (self._dns_host, self.port), self.timeout, **extra_kw
  File "c:\Users\hp\AppData\Local\Programs\Python\Python37\lib\site-packages\urllib3\util\connection.py", line 95, in create_connection
    raise err
  File "c:\Users\hp\AppData\Local\Programs\Python\Python37\lib\site-packages\urllib3\util\connection.py", line 85, in create_connection
    sock.connect(sa)
socket.timeout: timed out

During handling of the above exception, another exception occurred:

Traceback (most recent call last):
  File "c:\Users\hp\AppData\Local\Programs\Python\Python37\lib\site-packages\botocore\httpsession.py", line 464, in send
    chunked=self._chunked(request.headers),
  File "c:\Users\hp\AppData\Local\Programs\Python\Python37\lib\site-packages\urllib3\connectionpool.py", line 788, in urlopen
    method, url, error=e, _pool=self, _stacktrace=sys.exc_info()[2]
  File "c:\Users\hp\AppData\Local\Programs\Python\Python37\lib\site-packages\urllib3\util\retry.py", line 525, in increment
    raise six.reraise(type(error), error, _stacktrace)
  File "c:\Users\hp\AppData\Local\Programs\Python\Python37\lib\site-packages\urllib3\packages\six.py", line 770, in reraise
    raise value
  File "c:\Users\hp\AppData\Local\Programs\Python\Python37\lib\site-packages\urllib3\connectionpool.py", line 710, in urlopen
    chunked=chunked,
  File "c:\Users\hp\AppData\Local\Programs\Python\Python37\lib\site-packages\urllib3\connectionpool.py", line 398, in _make_request
    conn.request(method, url, **httplib_request_kw)
  File "c:\Users\hp\AppData\Local\Programs\Python\Python37\lib\site-packages\urllib3\connection.py", line 239, in request
    super(HTTPConnection, self).request(method, url, body=body, headers=headers)
  File "c:\Users\hp\AppData\Local\Programs\Python\Python37\lib\http\client.py", line 1262, in request
    self._send_request(method, url, body, headers, encode_chunked)
  File "c:\Users\hp\AppData\Local\Programs\Python\Python37\lib\site-packages\botocore\awsrequest.py", line 95, in _send_request
    method, url, body, headers, *args, **kwargs
  File "c:\Users\hp\AppData\Local\Programs\Python\Python37\lib\http\client.py", line 1308, in _send_request
    self.endheaders(body, encode_chunked=encode_chunked)
  File "c:\Users\hp\AppData\Local\Programs\Python\Python37\lib\http\client.py", line 1257, in endheaders
    self._send_output(message_body, encode_chunked=encode_chunked)
  File "c:\Users\hp\AppData\Local\Programs\Python\Python37\lib\site-packages\botocore\awsrequest.py", line 123, in _send_output
    self.send(msg)
  File "c:\Users\hp\AppData\Local\Programs\Python\Python37\lib\site-packages\botocore\awsrequest.py", line 218, in send
    return super().send(str)
  File "c:\Users\hp\AppData\Local\Programs\Python\Python37\lib\http\client.py", line 968, in send
    self.connect()
  File "c:\Users\hp\AppData\Local\Programs\Python\Python37\lib\site-packages\urllib3\connection.py", line 205, in connect
    conn = self._new_conn()
  File "c:\Users\hp\AppData\Local\Programs\Python\Python37\lib\site-packages\urllib3\connection.py", line 182, in _new_conn
    % (self.host, self.timeout),
urllib3.exceptions.ConnectTimeoutError: (<botocore.awsrequest.AWSHTTPConnection object at 0x000001E700753A48>, 'Connection to 169.254.169.254 timed out. (connect timeout=1)')

During handling of the above exception, another exception occurred:

Traceback (most recent call last):
  File "c:\Users\hp\AppData\Local\Programs\Python\Python37\lib\site-packages\botocore\utils.py", line 457, in _fetch_metadata_token
    response = self._session.send(request.prepare())
  File "c:\Users\hp\AppData\Local\Programs\Python\Python37\lib\site-packages\botocore\httpsession.py", line 490, in send
    raise ConnectTimeoutError(endpoint_url=request.url, error=e)
botocore.exceptions.ConnectTimeoutError: Connect timeout on endpoint URL: "http://169.254.169.254/latest/api/token"
DEBUG:urllib3.connectionpool:Starting new HTTP connection (2): 169.254.169.254:80
DEBUG:botocore.utils:Caught retryable HTTP exception while making metadata service request to http://169.254.169.254/latest/meta-data/iam/security-credentials/: Connect timeout on endpoint URL: "http://169.254.169.254/latest/meta-data/iam/security-credentials/"
Traceback (most recent call last):
  File "c:\Users\hp\AppData\Local\Programs\Python\Python37\lib\site-packages\urllib3\connection.py", line 175, in _new_conn
    (self._dns_host, self.port), self.timeout, **extra_kw
  File "c:\Users\hp\AppData\Local\Programs\Python\Python37\lib\site-packages\urllib3\util\connection.py", line 95, in create_connection
    raise err
  File "c:\Users\hp\AppData\Local\Programs\Python\Python37\lib\site-packages\urllib3\util\connection.py", line 85, in create_connection
    sock.connect(sa)
socket.timeout: timed out

During handling of the above exception, another exception occurred:

Traceback (most recent call last):
  File "c:\Users\hp\AppData\Local\Programs\Python\Python37\lib\site-packages\botocore\httpsession.py", line 464, in send
    chunked=self._chunked(request.headers),
  File "c:\Users\hp\AppData\Local\Programs\Python\Python37\lib\site-packages\urllib3\connectionpool.py", line 788, in urlopen
    method, url, error=e, _pool=self, _stacktrace=sys.exc_info()[2]
  File "c:\Users\hp\AppData\Local\Programs\Python\Python37\lib\site-packages\urllib3\util\retry.py", line 525, in increment
    raise six.reraise(type(error), error, _stacktrace)
  File "c:\Users\hp\AppData\Local\Programs\Python\Python37\lib\site-packages\urllib3\packages\six.py", line 770, in reraise
    raise value
  File "c:\Users\hp\AppData\Local\Programs\Python\Python37\lib\site-packages\urllib3\connectionpool.py", line 710, in urlopen
    chunked=chunked,
  File "c:\Users\hp\AppData\Local\Programs\Python\Python37\lib\site-packages\urllib3\connectionpool.py", line 398, in _make_request
    conn.request(method, url, **httplib_request_kw)
  File "c:\Users\hp\AppData\Local\Programs\Python\Python37\lib\site-packages\urllib3\connection.py", line 239, in request
    super(HTTPConnection, self).request(method, url, body=body, headers=headers)
  File "c:\Users\hp\AppData\Local\Programs\Python\Python37\lib\http\client.py", line 1262, in request
    self._send_request(method, url, body, headers, encode_chunked)
  File "c:\Users\hp\AppData\Local\Programs\Python\Python37\lib\site-packages\botocore\awsrequest.py", line 95, in _send_request
    method, url, body, headers, *args, **kwargs
  File "c:\Users\hp\AppData\Local\Programs\Python\Python37\lib\http\client.py", line 1308, in _send_request
    self.endheaders(body, encode_chunked=encode_chunked)
  File "c:\Users\hp\AppData\Local\Programs\Python\Python37\lib\http\client.py", line 1257, in endheaders
    self._send_output(message_body, encode_chunked=encode_chunked)
  File "c:\Users\hp\AppData\Local\Programs\Python\Python37\lib\site-packages\botocore\awsrequest.py", line 123, in _send_output
    self.send(msg)
  File "c:\Users\hp\AppData\Local\Programs\Python\Python37\lib\site-packages\botocore\awsrequest.py", line 218, in send
    return super().send(str)
  File "c:\Users\hp\AppData\Local\Programs\Python\Python37\lib\http\client.py", line 968, in send
    self.connect()
  File "c:\Users\hp\AppData\Local\Programs\Python\Python37\lib\site-packages\urllib3\connection.py", line 205, in connect
    conn = self._new_conn()
  File "c:\Users\hp\AppData\Local\Programs\Python\Python37\lib\site-packages\urllib3\connection.py", line 182, in _new_conn
    % (self.host, self.timeout),
urllib3.exceptions.ConnectTimeoutError: (<botocore.awsrequest.AWSHTTPConnection object at 0x000001E703467B08>, 'Connection to 169.254.169.254 timed out. (connect timeout=1)')

During handling of the above exception, another exception occurred:

Traceback (most recent call last):
  File "c:\Users\hp\AppData\Local\Programs\Python\Python37\lib\site-packages\botocore\utils.py", line 510, in _get_request
    response = self._session.send(request.prepare())
  File "c:\Users\hp\AppData\Local\Programs\Python\Python37\lib\site-packages\botocore\httpsession.py", line 490, in send
    raise ConnectTimeoutError(endpoint_url=request.url, error=e)
botocore.exceptions.ConnectTimeoutError: Connect timeout on endpoint URL: "http://169.254.169.254/latest/meta-data/iam/security-credentials/"
DEBUG:botocore.utils:Max number of attempts exceeded (1) when attempting to retrieve data from metadata service.
DEBUG:botocore.loaders:Loading JSON file: c:\Users\hp\AppData\Local\Programs\Python\Python37\lib\site-packages\botocore\data\endpoints.json
DEBUG:botocore.loaders:Loading JSON file: c:\Users\hp\AppData\Local\Programs\Python\Python37\lib\site-packages\botocore\data\sdk-default-configuration.json
DEBUG:botocore.hooks:Event choose-service-name: calling handler <function handle_service_name_alias at 0x000001E703136DC8>
DEBUG:botocore.loaders:Loading JSON file: c:\Users\hp\AppData\Local\Programs\Python\Python37\lib\site-packages\botocore\data\s3\2006-03-01\service-2.json
DEBUG:botocore.loaders:Loading JSON file: c:\Users\hp\AppData\Local\Programs\Python\Python37\lib\site-packages\botocore\data\s3\2006-03-01\endpoint-rule-set-1.json.gz
DEBUG:botocore.loaders:Loading JSON file: c:\Users\hp\AppData\Local\Programs\Python\Python37\lib\site-packages\botocore\data\partitions.json
DEBUG:botocore.hooks:Event creating-client-class.s3: calling handler <function add_generate_presigned_post at 0x000001E7030E18B8>
DEBUG:botocore.hooks:Event creating-client-class.s3: calling handler <function lazy_call.<locals>._handler at 0x000001E7020F7B88>
DEBUG:botocore.hooks:Event creating-client-class.s3: calling handler <function add_generate_presigned_url at 0x000001E7030E1678>
DEBUG:botocore.endpoint:Setting s3 timeout as (60, 60)
DEBUG:botocore.loaders:Loading JSON file: c:\Users\hp\AppData\Local\Programs\Python\Python37\lib\site-packages\botocore\data\_retry.json
DEBUG:botocore.client:Registering retry handlers for service: s3
DEBUG:botocore.utils:Registering S3 region redirector handler
